[2022-03-27 08:52:14,466] {taskinstance.py:1032} INFO - Dependencies all met for <TaskInstance: airflow_dag.ingest_drivers_task manual__2022-03-27T08:52:12.536581+00:00 [queued]>
[2022-03-27 08:52:14,483] {taskinstance.py:1032} INFO - Dependencies all met for <TaskInstance: airflow_dag.ingest_drivers_task manual__2022-03-27T08:52:12.536581+00:00 [queued]>
[2022-03-27 08:52:14,485] {taskinstance.py:1238} INFO - 
--------------------------------------------------------------------------------
[2022-03-27 08:52:14,487] {taskinstance.py:1239} INFO - Starting attempt 1 of 1
[2022-03-27 08:52:14,488] {taskinstance.py:1240} INFO - 
--------------------------------------------------------------------------------
[2022-03-27 08:52:14,629] {taskinstance.py:1259} INFO - Executing <Task(BashOperator): ingest_drivers_task> on 2022-03-27 08:52:12.536581+00:00
[2022-03-27 08:52:14,659] {standard_task_runner.py:52} INFO - Started process 133 to run task
[2022-03-27 08:52:14,708] {standard_task_runner.py:76} INFO - Running: ['***', 'tasks', 'run', '***_dag', 'ingest_drivers_task', 'manual__2022-03-27T08:52:12.536581+00:00', '--job-id', '132', '--raw', '--subdir', 'DAGS_FOLDER/***_dag.py', '--cfg-path', '/tmp/tmpbggj5o8i', '--error-file', '/tmp/tmpepn1wcco']
[2022-03-27 08:52:14,710] {standard_task_runner.py:77} INFO - Job 132: Subtask ingest_drivers_task
[2022-03-27 08:52:14,798] {logging_mixin.py:109} INFO - Running <TaskInstance: ***_dag.ingest_drivers_task manual__2022-03-27T08:52:12.536581+00:00 [running]> on host 072c0d4aaffc
[2022-03-27 08:52:14,950] {taskinstance.py:1426} INFO - Exporting the following env vars:
AIRFLOW_CTX_DAG_OWNER=Sourav Saha
AIRFLOW_CTX_DAG_ID=***_dag
AIRFLOW_CTX_TASK_ID=ingest_drivers_task
AIRFLOW_CTX_EXECUTION_DATE=2022-03-27T08:52:12.536581+00:00
AIRFLOW_CTX_DAG_RUN_ID=manual__2022-03-27T08:52:12.536581+00:00
[2022-03-27 08:52:14,967] {subprocess.py:62} INFO - Tmp dir root location: 
 /tmp
[2022-03-27 08:52:14,970] {subprocess.py:74} INFO - Running command: ['bash', '-c', 'python3 /opt/***/dags/ingest_drivers.py']
[2022-03-27 08:52:15,036] {subprocess.py:85} INFO - Output:
[2022-03-27 08:52:19,700] {subprocess.py:89} INFO - Traceback (most recent call last):
[2022-03-27 08:52:19,706] {subprocess.py:89} INFO -   File "/opt/***/dags/ingest_drivers.py", line 5, in <module>
[2022-03-27 08:52:19,717] {subprocess.py:89} INFO -     from oauth2client.client import GoogleCredentials
[2022-03-27 08:52:19,718] {subprocess.py:89} INFO - ModuleNotFoundError: No module named 'oauth2client'
[2022-03-27 08:52:20,014] {subprocess.py:93} INFO - Command exited with return code 1
[2022-03-27 08:52:20,084] {taskinstance.py:1700} ERROR - Task failed with exception
Traceback (most recent call last):
  File "/home/airflow/.local/lib/python3.7/site-packages/airflow/models/taskinstance.py", line 1329, in _run_raw_task
    self._execute_task_with_callbacks(context)
  File "/home/airflow/.local/lib/python3.7/site-packages/airflow/models/taskinstance.py", line 1455, in _execute_task_with_callbacks
    result = self._execute_task(context, self.task)
  File "/home/airflow/.local/lib/python3.7/site-packages/airflow/models/taskinstance.py", line 1511, in _execute_task
    result = execute_callable(context=context)
  File "/home/airflow/.local/lib/python3.7/site-packages/airflow/operators/bash.py", line 188, in execute
    f'Bash command failed. The command returned a non-zero exit code {result.exit_code}.'
airflow.exceptions.AirflowException: Bash command failed. The command returned a non-zero exit code 1.
[2022-03-27 08:52:20,100] {taskinstance.py:1277} INFO - Marking task as FAILED. dag_id=***_dag, task_id=ingest_drivers_task, execution_date=20220327T085212, start_date=20220327T085214, end_date=20220327T085220
[2022-03-27 08:52:20,151] {standard_task_runner.py:92} ERROR - Failed to execute job 132 for task ingest_drivers_task
Traceback (most recent call last):
  File "/home/airflow/.local/lib/python3.7/site-packages/airflow/task/task_runner/standard_task_runner.py", line 85, in _start_by_fork
    args.func(args, dag=self.dag)
  File "/home/airflow/.local/lib/python3.7/site-packages/airflow/cli/cli_parser.py", line 48, in command
    return func(*args, **kwargs)
  File "/home/airflow/.local/lib/python3.7/site-packages/airflow/utils/cli.py", line 92, in wrapper
    return f(*args, **kwargs)
  File "/home/airflow/.local/lib/python3.7/site-packages/airflow/cli/commands/task_command.py", line 298, in task_run
    _run_task_by_selected_method(args, dag, ti)
  File "/home/airflow/.local/lib/python3.7/site-packages/airflow/cli/commands/task_command.py", line 107, in _run_task_by_selected_method
    _run_raw_task(args, ti)
  File "/home/airflow/.local/lib/python3.7/site-packages/airflow/cli/commands/task_command.py", line 184, in _run_raw_task
    error_file=args.error_file,
  File "/home/airflow/.local/lib/python3.7/site-packages/airflow/utils/session.py", line 70, in wrapper
    return func(*args, session=session, **kwargs)
  File "/home/airflow/.local/lib/python3.7/site-packages/airflow/models/taskinstance.py", line 1329, in _run_raw_task
    self._execute_task_with_callbacks(context)
  File "/home/airflow/.local/lib/python3.7/site-packages/airflow/models/taskinstance.py", line 1455, in _execute_task_with_callbacks
    result = self._execute_task(context, self.task)
  File "/home/airflow/.local/lib/python3.7/site-packages/airflow/models/taskinstance.py", line 1511, in _execute_task
    result = execute_callable(context=context)
  File "/home/airflow/.local/lib/python3.7/site-packages/airflow/operators/bash.py", line 188, in execute
    f'Bash command failed. The command returned a non-zero exit code {result.exit_code}.'
airflow.exceptions.AirflowException: Bash command failed. The command returned a non-zero exit code 1.
[2022-03-27 08:52:20,176] {local_task_job.py:154} INFO - Task exited with return code 1
[2022-03-27 08:52:20,248] {local_task_job.py:264} INFO - 0 downstream tasks scheduled from follow-on schedule check
